<sdf version='1.6'>
  <world name='default'>
    <model name='ground_plane'>
      <static>1</static>
      <link name='link'>
        <collision name='collision'>
          <geometry>
            <plane>
              <normal>0 0 1</normal>
              <size>100 100</size>
            </plane>
          </geometry>
          <surface>
            <friction>
              <ode>
                <mu>100</mu>
                <mu2>50</mu2>
              </ode>
              <torsional>
                <ode/>
              </torsional>
            </friction>
            <contact>
              <ode/>
            </contact>
            <bounce/>
          </surface>
          <max_contacts>10</max_contacts>
        </collision>
        <visual name='visual'>
          <cast_shadows>0</cast_shadows>
          <geometry>
            <plane>
              <normal>0 0 1</normal>
              <size>100 100</size>
            </plane>
          </geometry>
          <material>
            <script>
              <uri>file://media/materials/scripts/gazebo.material</uri>
              <name>Gazebo/Grey</name>
            </script>
          </material>
        </visual>
        <self_collide>0</self_collide>
        <kinematic>0</kinematic>
        <gravity>1</gravity>
      </link>
    </model>
    <light name='sun' type='directional'>
      <cast_shadows>1</cast_shadows>
      <pose frame=''>0 0 10 0 -0 0</pose>
      <diffuse>0.8 0.8 0.8 1</diffuse>
      <specular>0.1 0.1 0.1 1</specular>
      <attenuation>
        <range>1000</range>
        <constant>0.9</constant>
        <linear>0.01</linear>
        <quadratic>0.001</quadratic>
      </attenuation>
      <direction>-0.5 0.5 -1</direction>
    </light>
    <gui fullscreen='0'>
      <camera name='user_camera'>
        <pose frame=''>9.11266 -3.76684 5.53167 0 0.439643 2.55219</pose>
        <view_controller>orbit</view_controller>
        <projection_type>perspective</projection_type>
      </camera>
    </gui>
    <gravity>0 0 -9.8</gravity>
    <magnetic_field>6e-06 2.3e-05 -4.2e-05</magnetic_field>
    <atmosphere type='adiabatic'/>
    <physics name='default_physics' default='0' type='ode'>
      <max_step_size>0.001</max_step_size>
      <real_time_factor>1</real_time_factor>
      <real_time_update_rate>1000</real_time_update_rate>
    </physics>
    <scene>
      <ambient>0.4 0.4 0.4 1</ambient>
      <background>0.7 0.7 0.7 1</background>
      <shadows>1</shadows>
    </scene>
    <spherical_coordinates>
      <surface_model>EARTH_WGS84</surface_model>
      <latitude_deg>0</latitude_deg>
      <longitude_deg>0</longitude_deg>
      <elevation>0</elevation>
      <heading_deg>0</heading_deg>
    </spherical_coordinates>
    <model name='j2n6s300'>
      <link name='root'>
        <pose frame=''>0 0 0 0 -0 0</pose>
        <inertial>
          <pose frame=''>0 0 0.1255 0 -0 0</pose>
          <mass>0.46784</mass>
          <inertia>
            <ixx>0.000951271</ixx>
            <ixy>0</ixy>
            <ixz>0</ixz>
            <iyy>0.000951271</iyy>
            <iyz>0</iyz>
            <izz>0.000374272</izz>
          </inertia>
        </inertial>
        <collision name='root_collision'>
          <pose frame=''>0 0 0 0 -0 0</pose>
          <geometry>
            <box>
              <size>1e-05 1e-05 1e-05</size>
            </box>
          </geometry>
          <max_contacts>10</max_contacts>
          <surface>
            <contact>
              <ode/>
            </contact>
            <bounce/>
            <friction>
              <torsional>
                <ode/>
              </torsional>
              <ode/>
            </friction>
          </surface>
        </collision>
        <collision name='root_fixed_joint_lump__j2n6s300_link_base_collision_1'>
          <pose frame=''>0 0 0 0 -0 0</pose>
          <geometry>
            <mesh>
              <scale>1 1 1</scale>
              <uri>/home/caio/workspaces/jacob_ws/src/kinova-ros/kinova_description/meshes/base.dae</uri>
            </mesh>
          </geometry>
          <max_contacts>10</max_contacts>
          <surface>
            <contact>
              <ode/>
            </contact>
            <bounce/>
            <friction>
              <torsional>
                <ode/>
              </torsional>
              <ode/>
            </friction>
          </surface>
        </collision>
        <visual name='root_visual'>
          <pose frame=''>0 0 0 0 -0 0</pose>
          <geometry>
            <box>
              <size>1e-05 1e-05 1e-05</size>
            </box>
          </geometry>
        </visual>
        <visual name='root_fixed_joint_lump__j2n6s300_link_base_visual_1'>
          <pose frame=''>0 0 0 0 -0 0</pose>
          <geometry>
            <mesh>
              <scale>1 1 1</scale>
              <uri>/home/caio/workspaces/jacob_ws/src/kinova-ros/kinova_description/meshes/base.dae</uri>
            </mesh>
          </geometry>
        </visual>
        <self_collide>0</self_collide>
        <kinematic>0</kinematic>
        <gravity>1</gravity>
      </link>
      <joint name='connect_root_and_world' type='revolute'>
        <child>root</child>
        <parent>world</parent>
        <axis>
          <limit>
            <lower>0</lower>
            <upper>0</upper>
          </limit>
          <dynamics>
            <damping>0</damping>
            <friction>0</friction>
            <spring_reference>0</spring_reference>
            <spring_stiffness>0</spring_stiffness>
          </dynamics>
          <use_parent_model_frame>1</use_parent_model_frame>
          <xyz>0 0 1</xyz>
        </axis>
      </joint>
      <link name='j2n6s300_link_1'>
        <pose frame=''>0 0 0.15675 3.14159 -0 3.14159</pose>
        <inertial>
          <pose frame=''>0 -0.002 -0.0605 0 -0 0</pose>
          <mass>0.7477</mass>
          <inertia>
            <ixx>0.00152032</ixx>
            <ixy>0</ixy>
            <ixz>0</ixz>
            <iyy>0.00152032</iyy>
            <iyz>0</iyz>
            <izz>0.00059816</izz>
          </inertia>
        </inertial>
        <collision name='j2n6s300_link_1_collision'>
          <pose frame=''>0 0 0 0 -0 0</pose>
          <geometry>
            <mesh>
              <scale>1 1 1</scale>
              <uri>/home/caio/workspaces/jacob_ws/src/kinova-ros/kinova_description/meshes/shoulder.dae</uri>
            </mesh>
          </geometry>
          <max_contacts>10</max_contacts>
          <surface>
            <contact>
              <ode/>
            </contact>
            <bounce/>
            <friction>
              <torsional>
                <ode/>
              </torsional>
              <ode/>
            </friction>
          </surface>
        </collision>
        <visual name='j2n6s300_link_1_visual'>
          <pose frame=''>0 0 0 0 -0 0</pose>
          <geometry>
            <mesh>
              <scale>1 1 1</scale>
              <uri>/home/caio/workspaces/jacob_ws/src/kinova-ros/kinova_description/meshes/shoulder.dae</uri>
            </mesh>
          </geometry>
        </visual>
        <visual name='j2n6s300_link_1_visual_1'>
          <pose frame=''>0 0 0 0 -0 0</pose>
          <geometry>
            <mesh>
              <scale>1 1 1</scale>
              <uri>/home/caio/workspaces/jacob_ws/src/kinova-ros/kinova_description/meshes/ring_big.STL</uri>
            </mesh>
          </geometry>
        </visual>
        <self_collide>0</self_collide>
        <kinematic>0</kinematic>
        <gravity>1</gravity>
      </link>
      <joint name='j2n6s300_joint_1' type='revolute'>
        <child>j2n6s300_link_1</child>
        <parent>root</parent>
        <axis>
          <xyz>0 0 -1</xyz>
          <limit>
            <lower>-1e+16</lower>
            <upper>1e+16</upper>
          </limit>
          <dynamics>
            <damping>0</damping>
            <friction>0</friction>
            <spring_reference>0</spring_reference>
            <spring_stiffness>0</spring_stiffness>
          </dynamics>
          <use_parent_model_frame>1</use_parent_model_frame>
        </axis>
      </joint>
      <link name='j2n6s300_link_2'>
        <pose frame=''>0 0.0016 0.2755 1.5708 -0 0</pose>
        <inertial>
          <pose frame=''>0 -0.2065 -0.01 0 -0 0</pose>
          <mass>0.99</mass>
          <inertia>
            <ixx>0.0105022</ixx>
            <ixy>0</ixy>
            <ixz>0</ixz>
            <iyy>0.000792</iyy>
            <iyz>0</iyz>
            <izz>0.0105022</izz>
          </inertia>
        </inertial>
        <collision name='j2n6s300_link_2_collision'>
          <pose frame=''>0 0 0 0 -0 0</pose>
          <geometry>
            <mesh>
              <scale>1 1 1</scale>
              <uri>/home/caio/workspaces/jacob_ws/src/kinova-ros/kinova_description/meshes/arm.dae</uri>
            </mesh>
          </geometry>
          <max_contacts>10</max_contacts>
          <surface>
            <contact>
              <ode/>
            </contact>
            <bounce/>
            <friction>
              <torsional>
                <ode/>
              </torsional>
              <ode/>
            </friction>
          </surface>
        </collision>
        <visual name='j2n6s300_link_2_visual'>
          <pose frame=''>0 0 0 0 -0 0</pose>
          <geometry>
            <mesh>
              <scale>1 1 1</scale>
              <uri>/home/caio/workspaces/jacob_ws/src/kinova-ros/kinova_description/meshes/arm.dae</uri>
            </mesh>
          </geometry>
        </visual>
        <visual name='j2n6s300_link_2_visual_1'>
          <pose frame=''>0 0 0 0 -0 0</pose>
          <geometry>
            <mesh>
              <scale>1 1 1</scale>
              <uri>/home/caio/workspaces/jacob_ws/src/kinova-ros/kinova_description/meshes/ring_big.STL</uri>
            </mesh>
          </geometry>
        </visual>
        <self_collide>0</self_collide>
        <kinematic>0</kinematic>
        <gravity>1</gravity>
      </link>
      <joint name='j2n6s300_joint_2' type='revolute'>
        <child>j2n6s300_link_2</child>
        <parent>j2n6s300_link_1</parent>
        <axis>
          <xyz>0 -1 0</xyz>
          <limit>
            <lower>1</lower>
            <upper>5.46288</upper>
            <effort>2000</effort>
            <velocity>1</velocity>
          </limit>
          <dynamics>
            <damping>0</damping>
            <friction>0</friction>
            <spring_reference>0</spring_reference>
            <spring_stiffness>0</spring_stiffness>
          </dynamics>
          <use_parent_model_frame>1</use_parent_model_frame>
        </axis>
      </joint>
      <link name='j2n6s300_link_3'>
        <pose frame=''>-0 0.0016 -0.1345 1.5708 -0 3.14159</pose>
        <inertial>
          <pose frame=''>0 0.081 -0.0086 0 -0 0</pose>
          <mass>0.6763</mass>
          <inertia>
            <ixx>0.00142022</ixx>
            <ixy>0</ixy>
            <ixz>0</ixz>
            <iyy>0.000304335</iyy>
            <iyz>0</iyz>
            <izz>0.00142022</izz>
          </inertia>
        </inertial>
        <collision name='j2n6s300_link_3_collision'>
          <pose frame=''>0 0 0 0 -0 0</pose>
          <geometry>
            <mesh>
              <scale>1 1 1</scale>
              <uri>/home/caio/workspaces/jacob_ws/src/kinova-ros/kinova_description/meshes/forearm.dae</uri>
            </mesh>
          </geometry>
          <max_contacts>10</max_contacts>
          <surface>
            <contact>
              <ode/>
            </contact>
            <bounce/>
            <friction>
              <torsional>
                <ode/>
              </torsional>
              <ode/>
            </friction>
          </surface>
        </collision>
        <visual name='j2n6s300_link_3_visual'>
          <pose frame=''>0 0 0 0 -0 0</pose>
          <geometry>
            <mesh>
              <scale>1 1 1</scale>
              <uri>/home/caio/workspaces/jacob_ws/src/kinova-ros/kinova_description/meshes/forearm.dae</uri>
            </mesh>
          </geometry>
        </visual>
        <visual name='j2n6s300_link_3_visual_1'>
          <pose frame=''>0 0 0 0 -0 0</pose>
          <geometry>
            <mesh>
              <scale>1 1 1</scale>
              <uri>/home/caio/workspaces/jacob_ws/src/kinova-ros/kinova_description/meshes/ring_big.STL</uri>
            </mesh>
          </geometry>
        </visual>
        <self_collide>0</self_collide>
        <kinematic>0</kinematic>
        <gravity>1</gravity>
      </link>
      <joint name='j2n6s300_joint_3' type='revolute'>
        <child>j2n6s300_link_3</child>
        <parent>j2n6s300_link_2</parent>
        <axis>
          <xyz>0 1 0</xyz>
          <limit>
            <lower>0.331613</lower>
            <upper>5.95157</upper>
            <effort>2000</effort>
            <velocity>1</velocity>
          </limit>
          <dynamics>
            <damping>0</damping>
            <friction>0</friction>
            <spring_reference>0</spring_reference>
            <spring_stiffness>0</spring_stiffness>
          </dynamics>
          <use_parent_model_frame>1</use_parent_model_frame>
        </axis>
      </joint>
      <link name='j2n6s300_link_4'>
        <pose frame=''>-0 -0.0098 0.0728 -3.14159 0 0</pose>
        <inertial>
          <pose frame=''>0 -0.037 -0.0642 0 -0 0</pose>
          <mass>0.426367</mass>
          <inertia>
            <ixx>7.73497e-05</ixx>
            <ixy>0</ixy>
            <ixz>0</ixz>
            <iyy>7.73497e-05</iyy>
            <iyz>0</iyz>
            <izz>0.0001428</izz>
          </inertia>
        </inertial>
        <collision name='j2n6s300_link_4_collision'>
          <pose frame=''>0 0 0 0 -0 0</pose>
          <geometry>
            <mesh>
              <scale>1 1 1</scale>
              <uri>/home/caio/workspaces/jacob_ws/src/kinova-ros/kinova_description/meshes/wrist.dae</uri>
            </mesh>
          </geometry>
          <max_contacts>10</max_contacts>
          <surface>
            <contact>
              <ode/>
            </contact>
            <bounce/>
            <friction>
              <torsional>
                <ode/>
              </torsional>
              <ode/>
            </friction>
          </surface>
        </collision>
        <visual name='j2n6s300_link_4_visual'>
          <pose frame=''>0 0 0 0 -0 0</pose>
          <geometry>
            <mesh>
              <scale>1 1 1</scale>
              <uri>/home/caio/workspaces/jacob_ws/src/kinova-ros/kinova_description/meshes/wrist.dae</uri>
            </mesh>
          </geometry>
        </visual>
        <visual name='j2n6s300_link_4_visual_1'>
          <pose frame=''>0 0 0 0 -0 0</pose>
          <geometry>
            <mesh>
              <scale>1 1 1</scale>
              <uri>/home/caio/workspaces/jacob_ws/src/kinova-ros/kinova_description/meshes/ring_small.STL</uri>
            </mesh>
          </geometry>
        </visual>
        <self_collide>0</self_collide>
        <kinematic>0</kinematic>
        <gravity>1</gravity>
      </link>
      <joint name='j2n6s300_joint_4' type='revolute'>
        <child>j2n6s300_link_4</child>
        <parent>j2n6s300_link_3</parent>
        <axis>
          <xyz>0 0 -1</xyz>
          <limit>
            <lower>-1e+16</lower>
            <upper>1e+16</upper>
          </limit>
          <dynamics>
            <damping>0</damping>
            <friction>0</friction>
            <spring_reference>0</spring_reference>
            <spring_stiffness>0</spring_stiffness>
          </dynamics>
          <use_parent_model_frame>1</use_parent_model_frame>
        </axis>
      </joint>
      <link name='j2n6s300_link_5'>
        <pose frame=''>0 0.02723 0.13694 -2.0944 -0 3.14159</pose>
        <inertial>
          <pose frame=''>0 -0.037 -0.0642 0 -0 0</pose>
          <mass>0.426367</mass>
          <inertia>
            <ixx>7.73497e-05</ixx>
            <ixy>0</ixy>
            <ixz>0</ixz>
            <iyy>7.73497e-05</iyy>
            <iyz>0</iyz>
            <izz>0.0001428</izz>
          </inertia>
        </inertial>
        <collision name='j2n6s300_link_5_collision'>
          <pose frame=''>0 0 0 0 -0 0</pose>
          <geometry>
            <mesh>
              <scale>1 1 1</scale>
              <uri>/home/caio/workspaces/jacob_ws/src/kinova-ros/kinova_description/meshes/wrist.dae</uri>
            </mesh>
          </geometry>
          <max_contacts>10</max_contacts>
          <surface>
            <contact>
              <ode/>
            </contact>
            <bounce/>
            <friction>
              <torsional>
                <ode/>
              </torsional>
              <ode/>
            </friction>
          </surface>
        </collision>
        <visual name='j2n6s300_link_5_visual'>
          <pose frame=''>0 0 0 0 -0 0</pose>
          <geometry>
            <mesh>
              <scale>1 1 1</scale>
              <uri>/home/caio/workspaces/jacob_ws/src/kinova-ros/kinova_description/meshes/wrist.dae</uri>
            </mesh>
          </geometry>
        </visual>
        <visual name='j2n6s300_link_5_visual_1'>
          <pose frame=''>0 0 0 0 -0 0</pose>
          <geometry>
            <mesh>
              <scale>1 1 1</scale>
              <uri>/home/caio/workspaces/jacob_ws/src/kinova-ros/kinova_description/meshes/ring_small.STL</uri>
            </mesh>
          </geometry>
        </visual>
        <self_collide>0</self_collide>
        <kinematic>0</kinematic>
        <gravity>1</gravity>
      </link>
      <joint name='j2n6s300_joint_5' type='revolute'>
        <child>j2n6s300_link_5</child>
        <parent>j2n6s300_link_4</parent>
        <axis>
          <xyz>0 -0.866025 -0.5</xyz>
          <limit>
            <lower>-1e+16</lower>
            <upper>1e+16</upper>
          </limit>
          <dynamics>
            <damping>0</damping>
            <friction>0</friction>
            <spring_reference>0</spring_reference>
            <spring_stiffness>0</spring_stiffness>
          </dynamics>
          <use_parent_model_frame>1</use_parent_model_frame>
        </axis>
      </joint>
      <link name='j2n6s300_link_6'>
        <pose frame=''>0 0.064262 0.201079 -3.14159 0 0</pose>
        <inertial>
          <pose frame=''>1e-06 0 -0.059999 0 -0 0</pose>
          <mass>0.99001</mass>
          <inertia>
            <ixx>0.000346461</ixx>
            <ixy>0</ixy>
            <ixz>-5.84994e-08</ixz>
            <iyy>0.000346486</iyy>
            <iyz>0</iyz>
            <izz>0.000582625</izz>
          </inertia>
        </inertial>
        <collision name='j2n6s300_link_6_collision'>
          <pose frame=''>0 0 0 0 -0 0</pose>
          <geometry>
            <mesh>
              <scale>1 1 1</scale>
              <uri>/home/caio/workspaces/jacob_ws/src/kinova-ros/kinova_description/meshes/hand_3finger.dae</uri>
            </mesh>
          </geometry>
          <max_contacts>10</max_contacts>
          <surface>
            <contact>
              <ode/>
            </contact>
            <bounce/>
            <friction>
              <torsional>
                <ode/>
              </torsional>
              <ode/>
            </friction>
          </surface>
        </collision>
        <collision name='j2n6s300_link_6_fixed_joint_lump__camera_link_collision_1'>
          <pose frame=''>0.05 0 0.057 0 -0 0</pose>
          <geometry>
            <mesh>
              <scale>1 1 1</scale>
              <uri>/home/caio/workspaces/jacob_ws/src/jacob_description/meshes/Genie_Nano.dae</uri>
            </mesh>
          </geometry>
          <surface>
            <contact>
              <ode/>
            </contact>
            <friction>
              <ode/>
              <torsional>
                <ode/>
              </torsional>
            </friction>
            <bounce/>
          </surface>
          <max_contacts>10</max_contacts>
        </collision>
        <collision name='j2n6s300_link_6_fixed_joint_lump__j2n6s300_end_effector_collision_2'>
          <pose frame=''>0 0 -0.16 -3.14159 -0 1.5708</pose>
          <geometry>
            <box>
              <size>1e-05 1e-05 1e-05</size>
            </box>
          </geometry>
          <max_contacts>10</max_contacts>
          <surface>
            <contact>
              <ode/>
            </contact>
            <bounce/>
            <friction>
              <torsional>
                <ode/>
              </torsional>
              <ode/>
            </friction>
          </surface>
        </collision>
        <visual name='j2n6s300_link_6_visual'>
          <pose frame=''>0 0 0 0 -0 0</pose>
          <geometry>
            <mesh>
              <scale>1 1 1</scale>
              <uri>/home/caio/workspaces/jacob_ws/src/kinova-ros/kinova_description/meshes/hand_3finger.dae</uri>
            </mesh>
          </geometry>
        </visual>
        <visual name='j2n6s300_link_6_visual_1'>
          <pose frame=''>0 0 0 0 -0 0</pose>
          <geometry>
            <mesh>
              <scale>1 1 1</scale>
              <uri>/home/caio/workspaces/jacob_ws/src/kinova-ros/kinova_description/meshes/ring_small.STL</uri>
            </mesh>
          </geometry>
        </visual>
        <visual name='j2n6s300_link_6_fixed_joint_lump__camera_link_visual_2'>
          <pose frame=''>0.05 0 0.057 1.5707 -0 -1.5707</pose>
          <geometry>
            <mesh>
              <scale>1 1 1</scale>
              <uri>/home/caio/workspaces/jacob_ws/src/jacob_description/meshes/Genie_Nano.dae</uri>
            </mesh>
          </geometry>
          <material>
            <script>
              <uri>__default__</uri>
              <name>__default__</name>
            </script>
          </material>
        </visual>
        <visual name='j2n6s300_link_6_fixed_joint_lump__j2n6s300_end_effector_visual_3'>
          <pose frame=''>0 0 -0.16 -3.14159 -0 1.5708</pose>
          <geometry>
            <box>
              <size>1e-05 1e-05 1e-05</size>
            </box>
          </geometry>
        </visual>
        <gravity>1</gravity>
        <velocity_decay/>
        <self_collide>0</self_collide>
        <sensor name='camera' type='camera'>
          <update_rate>22.7</update_rate>
          <camera name='head'>
            <horizontal_fov>1.39626</horizontal_fov>
            <image>
              <width>800</width>
              <height>800</height>
              <format>R8G8B8</format>
            </image>
            <clip>
              <near>0.02</near>
              <far>300</far>
            </clip>
            <noise>
              <type>gaussian</type>
              <mean>0</mean>
              <stddev>0.007</stddev>
            </noise>
          </camera>
          <plugin name='camera_controller' filename='libgazebo_ros_camera.so'>
            <alwaysOn>true</alwaysOn>
            <updateRate>0.0</updateRate>
            <cameraName>camera</cameraName>
            <imageTopicName>image_raw</imageTopicName>
            <cameraInfoTopicName>camera_info</cameraInfoTopicName>
            <frameName>camera_link</frameName>
            <hackBaseline>0.07</hackBaseline>
            <distortionK1>0.0</distortionK1>
            <distortionK2>0.0</distortionK2>
            <distortionK3>0.0</distortionK3>
            <distortionT1>0.0</distortionT1>
            <distortionT2>0.0</distortionT2>
            <robotNamespace>/</robotNamespace>
          </plugin>
          <pose frame=''>0.05 0 0.057 0 -0 0</pose>
        </sensor>
        <kinematic>0</kinematic>
      </link>
      <joint name='j2n6s300_joint_6' type='revolute'>
        <child>j2n6s300_link_6</child>
        <parent>j2n6s300_link_5</parent>
        <axis>
          <xyz>0 0 -1</xyz>
          <limit>
            <lower>-1e+16</lower>
            <upper>1e+16</upper>
          </limit>
          <dynamics>
            <damping>0</damping>
            <friction>0</friction>
            <spring_reference>0</spring_reference>
            <spring_stiffness>0</spring_stiffness>
          </dynamics>
          <use_parent_model_frame>1</use_parent_model_frame>
        </axis>
      </joint>
      <link name='j2n6s300_link_finger_1'>
        <pose frame=''>0.00279 0.033002 0.315749 1.5708 -0.649262 -1.35961</pose>
        <inertial>
          <pose frame=''>0.044 -0.0015 0 0 -0 0</pose>
          <mass>0.02</mass>
          <inertia>
            <ixx>1.62499e-06</ixx>
            <ixy>6.6e-07</ixy>
            <ixz>0</ixz>
            <iyy>1.126e-05</iyy>
            <iyz>0</iyz>
            <izz>9.885e-06</izz>
          </inertia>
        </inertial>
        <collision name='j2n6s300_link_finger_1_collision'>
          <pose frame=''>0 0 0 0 -0 0</pose>
          <geometry>
            <mesh>
              <scale>1 1 1</scale>
              <uri>/home/caio/workspaces/jacob_ws/src/kinova-ros/kinova_description/meshes/finger_proximal.dae</uri>
            </mesh>
          </geometry>
          <max_contacts>10</max_contacts>
          <surface>
            <contact>
              <ode/>
            </contact>
            <bounce/>
            <friction>
              <torsional>
                <ode/>
              </torsional>
              <ode/>
            </friction>
          </surface>
        </collision>
        <collision name='j2n6s300_link_finger_1_fixed_joint_lump__j2n6s300_link_finger_tip_1_collision_1'>
          <pose frame=''>0.044 -0.003 0 0 -0 0</pose>
          <geometry>
            <mesh>
              <scale>1 1 1</scale>
              <uri>/home/caio/workspaces/jacob_ws/src/kinova-ros/kinova_description/meshes/finger_distal.dae</uri>
            </mesh>
          </geometry>
          <max_contacts>10</max_contacts>
          <surface>
            <contact>
              <ode/>
            </contact>
            <bounce/>
            <friction>
              <torsional>
                <ode/>
              </torsional>
              <ode/>
            </friction>
          </surface>
        </collision>
        <visual name='j2n6s300_link_finger_1_visual'>
          <pose frame=''>0 0 0 0 -0 0</pose>
          <geometry>
            <mesh>
              <scale>1 1 1</scale>
              <uri>/home/caio/workspaces/jacob_ws/src/kinova-ros/kinova_description/meshes/finger_proximal.dae</uri>
            </mesh>
          </geometry>
        </visual>
        <visual name='j2n6s300_link_finger_1_fixed_joint_lump__j2n6s300_link_finger_tip_1_visual_1'>
          <pose frame=''>0.044 -0.003 0 0 -0 0</pose>
          <geometry>
            <mesh>
              <scale>1 1 1</scale>
              <uri>/home/caio/workspaces/jacob_ws/src/kinova-ros/kinova_description/meshes/finger_distal.dae</uri>
            </mesh>
          </geometry>
        </visual>
        <self_collide>0</self_collide>
        <kinematic>0</kinematic>
        <gravity>1</gravity>
      </link>
      <joint name='j2n6s300_joint_finger_1' type='revolute'>
        <child>j2n6s300_link_finger_1</child>
        <parent>j2n6s300_link_6</parent>
        <axis>
          <xyz>-0.977783 -0.209619 0</xyz>
          <limit>
            <lower>0</lower>
            <upper>2</upper>
            <effort>2000</effort>
            <velocity>1</velocity>
          </limit>
          <dynamics>
            <spring_reference>0</spring_reference>
            <spring_stiffness>0</spring_stiffness>
          </dynamics>
          <use_parent_model_frame>1</use_parent_model_frame>
        </axis>
      </joint>
      <link name='j2n6s300_link_finger_2'>
        <pose frame=''>0.02226 0.091332 0.315899 1.5708 -0.649262 1.38614</pose>
        <inertial>
          <pose frame=''>0.044 -0.0015 0 0 -0 0</pose>
          <mass>0.02</mass>
          <inertia>
            <ixx>1.62499e-06</ixx>
            <ixy>6.6e-07</ixy>
            <ixz>0</ixz>
            <iyy>1.126e-05</iyy>
            <iyz>0</iyz>
            <izz>9.885e-06</izz>
          </inertia>
        </inertial>
        <collision name='j2n6s300_link_finger_2_collision'>
          <pose frame=''>0 0 0 0 -0 0</pose>
          <geometry>
            <mesh>
              <scale>1 1 1</scale>
              <uri>/home/caio/workspaces/jacob_ws/src/kinova-ros/kinova_description/meshes/finger_proximal.dae</uri>
            </mesh>
          </geometry>
          <max_contacts>10</max_contacts>
          <surface>
            <contact>
              <ode/>
            </contact>
            <bounce/>
            <friction>
              <torsional>
                <ode/>
              </torsional>
              <ode/>
            </friction>
          </surface>
        </collision>
        <collision name='j2n6s300_link_finger_2_fixed_joint_lump__j2n6s300_link_finger_tip_2_collision_1'>
          <pose frame=''>0.044 -0.003 0 0 -0 0</pose>
          <geometry>
            <mesh>
              <scale>1 1 1</scale>
              <uri>/home/caio/workspaces/jacob_ws/src/kinova-ros/kinova_description/meshes/finger_distal.dae</uri>
            </mesh>
          </geometry>
          <max_contacts>10</max_contacts>
          <surface>
            <contact>
              <ode/>
            </contact>
            <bounce/>
            <friction>
              <torsional>
                <ode/>
              </torsional>
              <ode/>
            </friction>
          </surface>
        </collision>
        <visual name='j2n6s300_link_finger_2_visual'>
          <pose frame=''>0 0 0 0 -0 0</pose>
          <geometry>
            <mesh>
              <scale>1 1 1</scale>
              <uri>/home/caio/workspaces/jacob_ws/src/kinova-ros/kinova_description/meshes/finger_proximal.dae</uri>
            </mesh>
          </geometry>
        </visual>
        <visual name='j2n6s300_link_finger_2_fixed_joint_lump__j2n6s300_link_finger_tip_2_visual_1'>
          <pose frame=''>0.044 -0.003 0 0 -0 0</pose>
          <geometry>
            <mesh>
              <scale>1 1 1</scale>
              <uri>/home/caio/workspaces/jacob_ws/src/kinova-ros/kinova_description/meshes/finger_distal.dae</uri>
            </mesh>
          </geometry>
        </visual>
        <self_collide>0</self_collide>
        <kinematic>0</kinematic>
        <gravity>1</gravity>
      </link>
      <joint name='j2n6s300_joint_finger_2' type='revolute'>
        <child>j2n6s300_link_finger_2</child>
        <parent>j2n6s300_link_6</parent>
        <axis>
          <xyz>0.983 -0.183608 0</xyz>
          <limit>
            <lower>0</lower>
            <upper>2</upper>
            <effort>2000</effort>
            <velocity>1</velocity>
          </limit>
          <dynamics>
            <spring_reference>0</spring_reference>
            <spring_stiffness>0</spring_stiffness>
          </dynamics>
          <use_parent_model_frame>1</use_parent_model_frame>
        </axis>
      </joint>
      <link name='j2n6s300_link_finger_3'>
        <pose frame=''>-0.02226 0.091332 0.315899 1.5708 -0.649262 1.75545</pose>
        <inertial>
          <pose frame=''>0.044 -0.0015 0 0 -0 0</pose>
          <mass>0.02</mass>
          <inertia>
            <ixx>1.62499e-06</ixx>
            <ixy>6.6e-07</ixy>
            <ixz>0</ixz>
            <iyy>1.126e-05</iyy>
            <iyz>0</iyz>
            <izz>9.885e-06</izz>
          </inertia>
        </inertial>
        <collision name='j2n6s300_link_finger_3_collision'>
          <pose frame=''>0 0 0 0 -0 0</pose>
          <geometry>
            <mesh>
              <scale>1 1 1</scale>
              <uri>/home/caio/workspaces/jacob_ws/src/kinova-ros/kinova_description/meshes/finger_proximal.dae</uri>
            </mesh>
          </geometry>
          <max_contacts>10</max_contacts>
          <surface>
            <contact>
              <ode/>
            </contact>
            <bounce/>
            <friction>
              <torsional>
                <ode/>
              </torsional>
              <ode/>
            </friction>
          </surface>
        </collision>
        <collision name='j2n6s300_link_finger_3_fixed_joint_lump__j2n6s300_link_finger_tip_3_collision_1'>
          <pose frame=''>0.044 -0.003 0 0 -0 0</pose>
          <geometry>
            <mesh>
              <scale>1 1 1</scale>
              <uri>/home/caio/workspaces/jacob_ws/src/kinova-ros/kinova_description/meshes/finger_distal.dae</uri>
            </mesh>
          </geometry>
          <max_contacts>10</max_contacts>
          <surface>
            <contact>
              <ode/>
            </contact>
            <bounce/>
            <friction>
              <torsional>
                <ode/>
              </torsional>
              <ode/>
            </friction>
          </surface>
        </collision>
        <visual name='j2n6s300_link_finger_3_visual'>
          <pose frame=''>0 0 0 0 -0 0</pose>
          <geometry>
            <mesh>
              <scale>1 1 1</scale>
              <uri>/home/caio/workspaces/jacob_ws/src/kinova-ros/kinova_description/meshes/finger_proximal.dae</uri>
            </mesh>
          </geometry>
        </visual>
        <visual name='j2n6s300_link_finger_3_fixed_joint_lump__j2n6s300_link_finger_tip_3_visual_1'>
          <pose frame=''>0.044 -0.003 0 0 -0 0</pose>
          <geometry>
            <mesh>
              <scale>1 1 1</scale>
              <uri>/home/caio/workspaces/jacob_ws/src/kinova-ros/kinova_description/meshes/finger_distal.dae</uri>
            </mesh>
          </geometry>
        </visual>
        <self_collide>0</self_collide>
        <kinematic>0</kinematic>
        <gravity>1</gravity>
      </link>
      <joint name='j2n6s300_joint_finger_3' type='revolute'>
        <child>j2n6s300_link_finger_3</child>
        <parent>j2n6s300_link_6</parent>
        <axis>
          <xyz>0.983 0.183608 0</xyz>
          <limit>
            <lower>0</lower>
            <upper>2</upper>
            <effort>2000</effort>
            <velocity>1</velocity>
          </limit>
          <dynamics>
            <spring_reference>0</spring_reference>
            <spring_stiffness>0</spring_stiffness>
          </dynamics>
          <use_parent_model_frame>1</use_parent_model_frame>
        </axis>
      </joint>
      <static>0</static>
      <plugin name='gazebo_ros_control' filename='libgazebo_ros_control.so'>
        <robotNamespace>j2n6s300</robotNamespace>
        <robotSimType>gazebo_ros_control/DefaultRobotHWSim</robotSimType>
      </plugin>
      <pose frame=''>0 0 0 0 -0 0</pose>
    </model>
    <model name='april_box'>
      <link name='box'>
        <pose frame=''>0 0 0 0 -0 0</pose>
        <inertial>
          <pose frame=''>0 0 0 0 -0 0</pose>
          <mass>35.3365</mass>
          <inertia>
            <ixx>1.84916</ixx>
            <ixy>-0.000354</ixy>
            <ixz>-0.154188</ixz>
            <iyy>1.66267</iyy>
            <iyz>0.003292</iyz>
            <izz>0.802239</izz>
          </inertia>
        </inertial>
        <collision name='box_collision'>
          <pose frame=''>0 0 0 0 -0 0</pose>
          <geometry>
            <mesh>
              <scale>1 1 1</scale>
              <uri>/home/caio/workspaces/jacob_ws/src/jacob_description/meshes/april_box.dae</uri>
            </mesh>
          </geometry>
          <max_contacts>10</max_contacts>
          <surface>
            <contact>
              <ode/>
            </contact>
            <bounce/>
            <friction>
              <torsional>
                <ode/>
              </torsional>
              <ode/>
            </friction>
          </surface>
        </collision>
        <visual name='box_visual'>
          <pose frame=''>0 0 0 0 -0 0</pose>
          <geometry>
            <mesh>
              <scale>1 1 1</scale>
              <uri>/home/caio/workspaces/jacob_ws/src/jacob_description/meshes/april_box.dae</uri>
            </mesh>
          </geometry>
        </visual>
        <self_collide>0</self_collide>
        <kinematic>0</kinematic>
        <gravity>1</gravity>
      </link>
      <pose frame=''>0 0 0 0 -0 0</pose>
    </model>
    <state world_name='default'>
      <sim_time>200 893000000</sim_time>
      <real_time>233 901449456</real_time>
      <wall_time>1555280178 945191688</wall_time>
      <iterations>200893</iterations>
      <model name='april_box'>
        <pose frame=''>-4.09165 0.700423 1 -1.5708 1e-06 0.026416</pose>
        <scale>1 1 1</scale>
        <link name='box'>
          <pose frame=''>-4.09165 0.700423 1 -1.5708 1e-06 0.026416</pose>
          <velocity>0 0 0 0 -0 0</velocity>
          <acceleration>-2.39489 0.043737 6.2801 -0.22754 1.24759 0.028684</acceleration>
          <wrench>-84.6269 1.54551 221.917 0 -0 0</wrench>
        </link>
      </model>
      <model name='ground_plane'>
        <pose frame=''>0 0 0 0 -0 0</pose>
        <scale>1 1 1</scale>
        <link name='link'>
          <pose frame=''>0 0 0 0 -0 0</pose>
          <velocity>0 0 0 0 -0 0</velocity>
          <acceleration>0 0 0 0 -0 0</acceleration>
          <wrench>0 0 0 0 -0 0</wrench>
        </link>
      </model>
      <model name='j2n6s300'>
        <pose frame=''>-1.4e-05 -1.6e-05 6e-06 -2.8e-05 2.1e-05 -7e-06</pose>
        <scale>1 1 1</scale>
        <link name='j2n6s300_link_1'>
          <pose frame=''>-1.3e-05 -1.6e-05 0.156755 3.14155 1.3e-05 -3.14159</pose>
          <velocity>-0.000164 -0.000195 0.001168 0.00075 -0.00067 0.0428</velocity>
          <acceleration>-0.527271 0.61846 2.25301 2.37863 -1.03296 -2.32784</acceleration>
          <wrench>-0.39424 0.462422 1.68457 0 -0 0</wrench>
        </link>
        <link name='j2n6s300_link_2'>
          <pose frame=''>-1.6e-05 0.001578 0.275505 -1.57088 -0.24088 -3.14157</pose>
          <velocity>-0.000298 -0.00029 0.001199 0.001046 0.001282 0.042714</velocity>
          <acceleration>-0.166952 2.48948 2.02579 1.06152 -1.31223 0.889709</acceleration>
          <wrench>-0.165282 2.46458 2.00553 0 -0 0</wrench>
        </link>
        <link name='j2n6s300_link_3'>
          <pose frame=''>0.097793 0.001544 0.673668 -1.56804 1.53965 0.002772</pose>
          <velocity>0.000246 0.003445 0.001067 0.00105 0.052101 0.042785</velocity>
          <acceleration>1.20744 2.19297 0.956377 -2.30748 0.900758 -1.71766</acceleration>
          <wrench>0.816591 1.4831 0.646798 0 -0 0</wrench>
        </link>
        <link name='j2n6s300_link_4'>
          <pose frame=''>-0.109408 -0.009859 0.667215 1.53514 0.508316 1.55345</pose>
          <velocity>0.000897 -0.005983 0.010803 0.176916 0.055333 0.046434</velocity>
          <acceleration>2.36398 -2.56533 -1.71591 3.05297 -0.321843 -2.7713</acceleration>
          <wrench>1.00792 -1.09377 -0.731607 0 -0 0</wrench>
        </link>
        <link name='j2n6s300_link_5'>
          <pose frame=''>-0.17251 -0.02789 0.632889 -0.618086 0.32771 -0.420921</pose>
          <velocity>-6.9e-05 -0.003101 0.011107 0.15677 0.035941 0.015394</velocity>
          <acceleration>1.27742 -2.11386 -1.37838 0.224372 -0.365602 -2.88136</acceleration>
          <wrench>0.544649 -0.901279 -0.587695 0 -0 0</wrench>
        </link>
        <link name='j2n6s300_link_6'>
          <pose frame=''>-0.209081 -0.085305 0.603713 1.66522 -0.326458 2.72081</pose>
          <velocity>-0.000294 0.000938 0.003459 -0.06136 -0.48732 0.063096</velocity>
          <acceleration>-1.5823 -0.833395 -0.357209 1.06657 0.598339 -2.62844</acceleration>
          <wrench>-1.56649 -0.825069 -0.353641 0 -0 0</wrench>
        </link>
        <link name='j2n6s300_link_finger_1'>
          <pose frame=''>-0.244646 -0.19123 0.644325 -1.68697 -0.011118 -1.97039</pose>
          <velocity>-0.013607 0.001305 -0.007329 -0.422523 -0.336919 0.108783</velocity>
          <acceleration>7.5211 -4.65084 -2.21512 -1.59395 -0.547959 1.26582</acceleration>
          <wrench>0.150422 -0.093017 -0.044302 0 -0 0</wrench>
        </link>
        <link name='j2n6s300_link_finger_2'>
          <pose frame=''>-0.28078 -0.181248 0.595579 1.05355 -0.157388 -1.92248</pose>
          <velocity>0.009572 -0.003978 -0.025486 -0.478038 -0.293513 0.320631</velocity>
          <acceleration>-15.5239 7.39286 13.1096 -0.687672 -1.05754 0.422447</acceleration>
          <wrench>-0.310478 0.147857 0.262191 0 -0 0</wrench>
        </link>
        <link name='j2n6s300_link_finger_3'>
          <pose frame=''>-0.24229 -0.198473 0.581302 1.4262 -0.166117 -1.95002</pose>
          <velocity>0.017608 -0.002457 -0.005746 -0.250592 -0.408637 0.093132</velocity>
          <acceleration>-20.3365 6.56289 4.48005 0.030898 -0.750432 -0.544716</acceleration>
          <wrench>-0.40673 0.131258 0.089601 0 -0 0</wrench>
        </link>
        <link name='root'>
          <pose frame=''>-1.4e-05 -1.6e-05 6e-06 -2.8e-05 2.1e-05 -7e-06</pose>
          <velocity>-6e-06 -4e-06 0.001122 0.001033 -0.000893 -0.007312</velocity>
          <acceleration>-0.31065 0.494802 2.22482 0.268087 -0.201049 2.6684</acceleration>
          <wrench>-0.145334 0.231488 1.04086 0 -0 0</wrench>
        </link>
      </model>
      <light name='sun'>
        <pose frame=''>0 0 10 0 -0 0</pose>
      </light>
    </state>
  </world>
</sdf>
